Workbook

Sheet Cover
B1: RSM Impact Investing Case Competition 2025
B3: Table of Contents
B5: Outputs
B6: Inputs
B7: Model

Sheet Outputs
B1: Outputs
B3: Project Economics (Unlevered)
B6: Model Drivers Set To | E6: 2
B8: Metric | E8: Base | G8: Best | I8: Worst
B10: Unlevered IRR | E10: =E24 -> 0.15763643 | G10: =E23 -> 0.19776594 | I10: =E25 -> 0.11510612
B11: NPV @ 8,3% | E11: =F24 -> 3691.4991 | G11: =F23 -> 6131.7114 | I11: =F25 -> 1442.8589
B12: Payback | E12: =G24 -> 10 | G12: =G23 -> 9 | I12: =G25 -> 11
B13: EBITDA margin | E13: =I24 -> 0.24078389 | G13: =I23 -> 0.29766379 | I13: =I25 -> 0.18345986
B16: Stegra delivers 16 % unlevered IRR and 3557 m NPV @ 8 %, proving strong project economics before leverage.
B19: Scenario Summary
E21: Unlev IRR | F21: NPV | G21: Payback | H21: Gross M | I21: EBITDA M | J21: Equity IRR | K21: Min DSCR | L21: LLCR
E22: =Model!$F$191 -> 0.15763643 | F22: =Model!F193 -> 3691.4991 | G22: =Model!$F$195 -> 10 | H22: =Model!H93 -> 0.32639732 | I22: =Model!H98 -> 0.24078389 | J22: =Model!F305 -> 0.24344134 | K22: =Model!H261 -> 1.7492788 | L22: =Model!H267 -> 1.5304267
B23: Best Case | D23: 1 | E23: 0.19776594 | F23: 6131.7114 | G23: 9 | H23: 0.38200671 | I23: 0.29766379 | J23: 0.31591262 | K23: 2.2079643 | L23: 1.9641054
B24: Base Case | D24: 2 | E24: 0.15763643 | F24: 3691.4991 | G24: 10 | H24: 0.32639732 | I24: 0.24078389 | J24: 0.24344134 | K24: 1.7492788 | L24: 1.5304267
B25: Worst Case | D25: 3 | E25: 0.11510612 | F25: 1442.8589 | G25: 11 | H25: 0.27027233 | I25: 0.18345986 | J25: 0.16723693 | K25: 1.3250551 | L25: 1.1307804
B28: Best Case - It assumes a 30% green premium, 75% offtake coverage, and renewable power at €45/MWh due to optimized PPA sourcing. Pellet cost falls to €90/t.
B29: Base Case - It assumes a 25% green premium, 70% offtake coverage under long-term contracts, and renewable power at €50/MWh under the PPA. Pellet costs are set at €100/t, and inflation at 2%.
B30: Worst Case - Conservative stress conditions to test resilience. It assumes a 20% green premium, 65% offtake coverage (greater spot exposure), electricity cost €60/MWh, and pellet cost €110/t.
B33: Capital Structuring
B35: Model Drivers Set To | E35: 2
B38: Metric | E38: Project IRR | G38: Equity IRR | I38: Min DSCR | K38: Comment | M38: Debt | N38: Equity
E39: =Model!F191 -> 0.15763643 | G39: =Model!F305 -> 0.24344134 | I39: =Model!H261 -> 1.7492788
B40: Single Financial Close | D40: 1 | E40: 0.13305476 | F40: 0 | G40: 0.20486776 | H40: 0 | I40: 1.6108537 | K40: High debt, early risk | M40: =Inputs!$K$35 -> 0.6 | N40: =Inputs!$K$36 -> 0.4
B41: Two Phased | D41: 2 | E41: 0.15763643 | F41: 0 | G41: 0.24344134 | H41: 0 | I41: 1.7492788 | K41: Balanced risk return | M41: =Inputs!$K$35 -> 0.6 | N41: =Inputs!$K$36 -> 0.4
X44: 2025 | Y44: =X44+1 -> 2026 | Z44: =Y44+1 -> 2027 | AA44: =Z44+1 -> 2028 | AB44: =AA44+1 -> 2029
W45: Single Financial Close | X45: =Inputs!F143 -> 5500 | Y45: =Inputs!G143 -> 0 | Z45: =Inputs!H143 -> 0 | AA45: =Inputs!I143 -> 0 | AB45: =Inputs!J143 -> 0
W46: Two Phased | X46: =Inputs!F144 -> 1500 | Y46: =Inputs!G144 -> 1500 | Z46: =Inputs!H144 -> 1000 | AA46: =Inputs!I144 -> 1000 | AB46: =Inputs!J144 -> 500
B55: Phased financing reduces execution risk, smooths cash flows, and raises equity IRR (+5 pp) while keeping DSCR > 1.6× — the optimal for Stegra.
B57: Financing & Bankability
B60: Metric - Base Scenario | E60: Value | G60: Target / Comment
B62: Total Funding | E62: =Inputs!F40 -> 5500 | G62: 70% debt, 30% equity
B63: Operating Life | E63: 20 years
B64: Debt Tenor | E64: 20 | G64: For two-phased credit arrangements
B65: Debt, Rate | E65: =Inputs!F151 -> 0.06 | G65: EIB / EAC Standard
B66: WACC | E66: =Inputs!L79 -> 0.083159675 | G66: Projected Stegra's cost of capital
B68: DSCR | E68: =$M$24 -> 0 | G68: >= 1,3x Covenant 1
B69: LLCR | E69: =$N$24 -> 0 | G69: >= 1,3x Covenant 2
B70: Max Total Debt / EBITDA | E70: =AC75 -> 2.379205 | G70: <= 4,0x from Phase 2 Operations. Optional Covenant | Z70: =Model!H6 -> 2027 | AA70: =Model!I6 -> 2028 | AB70: =Model!J6 -> 2029 | AC70: =Model!K6 -> 2030 | AD70: =Model!L6 -> 2031 | AE70: =Model!M6 -> 2032 | AF70: =Model!N6 -> 2033 | AG70: =Model!O6 -> 2034 | ... AS70: =Model!AA6 -> 2046
B72: Equity IRR | E72: =J24 -> 0.24344134 | G72: > 15% PE hurdle rate | W72: EBITDA | Z72: =Model!H$97 -> 442.4232 | AA72: =Model!I$97 -> 560.26738 | AB72: =Model!J$97 -> 682.64835 | AC72: =Model!K$97 -> 1198.6209 | AD72: =Model!L$97 -> 1334.6645 | AE72: =Model!M$97 -> 1475.124 | AF72: =Model!N$97 -> 1500.893 | AG72: =Model!O$97 -> 1523.3019 | ... AS72: =Model!AA$97 -> 1728.7868
B73: Payback for Investors | E73: =L24 -> 1.5304267 | G73: Follows PE fund lifecycle | W73: Total Debt | Z73: =Model!H249 -> 1710 | AA73: =Model!I249 -> 1620 | AB73: =Model!J249 -> 3030 | AC73: =Model!K249 -> 2851.7647 | AD73: =Model!L249 -> 2673.5294 | AE73: =Model!M249 -> 2495.2941 | AF73: =Model!N249 -> 2317.0588 | AG73: =Model!O249 -> 2138.8235 | ... AS73: =Model!AA249 -> -1.9895197e-13
...

Sheet Inputs
B1: Model Drivers
B3: Input
B5: Operations | H5: Cost
B7: Construction Start/End Year = 2025 / 2026 | F7: 2025 / 2026 | H7: Electricity Cost (EUR/MWh) | L7: 50
B8: Operations Start (COD) | F8: 2027 | H8: Electricity demand for 2.5 Mt of production TWh | L8: 7
B9: Phase 1 Plant Capacity 2027 - 2029 (Mtpa) | F9: 2.5 | H9: Pellet Cost (EUR/t) | L9: 100
B10: Phase 2 Plant Capacity > 2030 (Mtpa) | F10: 5 | H10: Pellet Intensity, for 1tonne steel* | L10: 1.5
B11: Ramp Years to 100% = 3 (60% in 2027, 85% in 2028, 100% in 2029) | H11: Scrap Usage (tonnes/tonne steel)** | L11: 0.31
H12: Scrap Metal Price*** | L12: 385
B13: Revenue | H13: Consumables & Alloys *** | L13: 130
H14: Other (Logistics, Utilties) | L14: 95
B15: European HRC average 2023 (€/t) | F15: 800 | H15: FTE Operational Phase 1 | L15: 1500
B16: Tax rate, corporate Sweden | F16: 0.206 | H16: Direct Labor | L16: 750
H17: Indirect Labor | L17: 750
H18: FTE Operational Phase 2 Increase | L18: 0.4
H19: Direct Labor cost, (€/t) **** | L19: 49
H20: Labor cost average (EUR)**** | L20: 75000
H21: Other SG&A, % of Revenue | L21: 0.035
H22: R&D, % of Revenue | L22: 0.02
L24: It takes approximately 1.5 tons of DR-grade iron ore pellets to produce 1 ton of crude steel *
L25: 20-30% blend in EAF; common for green steel to maintain quality **
L26: 2025 average data; https://www.steelorbis.com/steel-market/scrap.htm ***
L27: Eurostat 2024 “Hourly Labour Costs in Manufacturing, Sweden; https://www.scb.se/en/finding-statistics/statistics-by-subject-area/labour-market/wages-salaries-and-labour-costs/ ****
B30: Sources & Uses
B32: All figures in EUR millions unless stated
B34: Uses of Cash | E34: % | F34: Amount | H34: Sources of Cash | K34: % | L34: Amount
B35: Construction and Operations | F35: 5500 | H35: Debt Term Loan | K35: 0.6 | L35: =K35*L40 -> 3300
B36: If Two-Phased Construction: | H36: Equity Value | K36: 0.4 | L36: =K36*L40 -> 2200
B37: Phase 1: | E37: =F37/F35 -> 0.54545455 | F37: 3000
B38: Phase 2: | E38: =F38/F35 -> 0.45454545 | F38: 2500
B40: Total Uses: | E40: 1 | F40: =F35+F39 -> 5500 | H40: Total Uses | K40: =K35+K36 -> 1 | L40: =F40 -> 5500
B43: Weighted Average Cost of Capital
B45: All figures in EUR millions unless stated
H47: Average | I47: Debt/ | J47: Debt/ | K47: Levered | L47: Unlevered
B48: Peers Group | D48: Region | F48: Debt | G48: Equity | H48: Tax Rate | I48: Equity | J48: Capital | K48: Beta | L48: Beta
B50: SSAB AB | D50: Europe | F50: 1200 | G50: 5000 | H50: 0.205 | I50: =F50/G50 -> 0.24 | J50: =F50/(F50+G50) -> 0.19354839 | K50: 1.15 | L50: =K50/(1+(1-H50)*I50) -> 0.96573732
B51: Outokumpu Oyj | D51: Europe | F51: 800 | G51: 2300 | H51: 0.182 | I51: =F51/G51 -> 0.34782609 | J51: =F51/(F51+G51) -> 0.25806452 | K51: 1.42 | L51: =K51/(1+(1-H51)*I51) -> 1.1054698
B52: Salzgitter AG | D52: Europe | F52: 2100 | G52: 3400 | H52: 0.281 | I52: =F52/G52 -> 0.61764706 | J52: =F52/(F52+G52) -> 0.38181818 | K52: 1.28 | L52: =K52/(1+(1-H52)*I52) -> 0.88637243
B53: ThyssenKrupp AG | D53: Europe | F53: 4500 | G53: 6800 | H53: 0.253 | I53: =F53/G53 -> 0.66176471 | J53: =F53/(F53+G53) -> 0.39823009 | K53: 1.55 | L53: =K53/(1+(1-H53)*I53) -> 1.0372484
G56: Average | H56: =AVERAGE(H50:H54) -> 0.23025 | I56: =AVERAGE(I50:I54) -> 0.46680946 | J56: =AVERAGE(J50:J54) -> 0.30791529 | K56: =AVERAGE(K50:K54) -> 1.35 | L56: =AVERAGE(L50:L54) -> 0.998707
...

Sheet Model
B1: Model
B3: Revenue Schedule
B5: All figures in EUR millions unless stated | H5: Operations - Phase 1 | K5: Operations - Phase 2
B6: {=CONCATENATE("Model Drivers: ",INDEX(Inputs!$B$96:$B$98,Inputs!$D$86)," & ",INDEX(Inputs!$B$143:$B$144,Inputs!$D$139)," Financing")} -> Model Drivers: Base Case & Two Phased Financing | F6: 2025 | G6: 2026 | H6: =Inputs!$F$8 -> 2027 | I6: =H6+1 -> 2028 | J6: =I6+1 -> 2029 | K6: =J6+1 -> 2030 | L6: =K6+1 -> 2031 | M6: =L6+1 -> 2032 | N6: =M6+1 -> 2033 | O6: =N6+1 -> 2034 | P6: =O6+1 -> 2035 | ... AA6: =Z6+1 -> 2046
B8: PRODUCTION CAPACITY
B9: Phase 1 Starting Capacity | D9: (Mtpa/Year) | H9: =Inputs!$F$9 -> 2.5 | I9: =Inputs!$F$9 -> 2.5 | J9: =Inputs!$F$9 -> 2.5 | K9: =Inputs!$F$9 -> 2.5 | L9: =Inputs!$F$9 -> 2.5 | M9: =Inputs!$F$9 -> 2.5 | N9: =Inputs!$F$9 -> 2.5 | O9: =Inputs!$F$9 -> 2.5 | ... AA9: =Inputs!$F$9 -> 2.5
B10: Phase 2 Additional Capacity | D10: (Mtpa/Year) | H10: 0 | I10: 0 | J10: 0 | K10: 2.5 | L10: 2.5 | M10: 2.5 | N10: 2.5 | O10: 2.5 | P10: 2.5 | Q10: 2.5 | R10: 2.5 | S10: 2.5 | T10: 2.5 | U10: 2.5 | V10: 2.5 | W10: 2.5 | X10: 2.5 | Y10: 2.5 | Z10: 2.5 | AA10: 2.5
B11: Total Capacity | D11: (Mtpa/Year) | H11: =SUM(H9:H10) -> 2.5 | I11: =SUM(I9:I10) -> 2.5 | J11: 0 | K11: =SUM(K9:K10) -> 5 | L11: =SUM(L9:L10) -> 5 | M11: =SUM(M9:M10) -> 5 | N11: =SUM(N9:N10) -> 5 | O11: =SUM(O9:O10) -> 5 | P11: =SUM(P9:P10) -> 5 | Q11: =SUM(Q9:Q10) -> 5 | R11: =SUM(R9:R10) -> 5 | ... AA11: =SUM(AA9:AA10) -> 5
B13: UTILISATION
B14: Utilisation Phase 1 | D14: ( % of Capacity) | H14: 0.7 | I14: 0.85 | J14: 1 | K14: 1 | L14: 1 | M14: 1 | N14: 1 | O14: 1 | P14: 1 | Q14: 1 | R14: 1 | S14: 1 | T14: 1 | U14: 1 | V14: 1 | W14: 1 | X14: 1 | Y14: 1 | Z14: 1 | AA14: 1
B15: Utilisation Phase 2 | D15: ( % of Capacity) | H15: 0 | I15: 0 | J15: 0 | K15: 0.7 | L15: 0.85 | M15: 1 | N15: 1 | O15: 1 | P15: 1 | Q15: 1 | R15: 1 | S15: 1 | T15: 1 | U15: 1 | V15: 1 | W15: 1 | X15: 1 | Y15: 1 | Z15: 1 | AA15: 1
B16: Total Plant Utilisation | H16: =AVERAGE(H14:H15) -> 0.35 | I16: =AVERAGE(I14:I15) -> 0.425 | J16: =AVERAGE(J14:J15) -> 0.5 | K16: =AVERAGE(K14:K15) -> 0.85 | L16: =AVERAGE(L14:L15) -> 0.925 | M16: =AVERAGE(M14:M15) -> 1 | N16: =AVERAGE(N14:N15) -> 1 | O16: =AVERAGE(O14:O15) -> 1 | ... AA16: =AVERAGE(AA14:AA15) -> 1
B18: OUTPUT
B19: Phase 1 Output | D19: (Mtpa/Year) | H19: =H9*H14 -> 1.75 | I19: =I9*I14 -> 2.125 | J19: =J9*J14 -> 2.5 | K19: =K9*K14 -> 2.5 | L19: =L9*L14 -> 2.5 | M19: =M9*M14 -> 2.5 | N19: =N9*N14 -> 2.5 | O19: =O9*O14 -> 2.5 | ... AA19: =AA9*AA14 -> 2.5
B20: Phase 2 Output | D20: (Mtpa/Year) | H20: =H10*H15 -> 0 | I20: =I10*I15 -> 0 | J20: =J10*J15 -> 0 | K20: =K10*K15 -> 1.75 | L20: =L10*L15 -> 2.125 | M20: =M10*M15 -> 2.5 | N20: =N10*N15 -> 2.5 | O20: =O10*O15 -> 2.5 | ... AA20: =AA10*AA15 -> 2.5
B21: Total Output | D21: (Mtpa/Year) | H21: =SUM(H19:H20) -> 1.75 | I21: =SUM(I19:I20) -> 2.125 | J21: =SUM(J19:J20) -> 2.5 | K21: =SUM(K19:K20) -> 4.25 | L21: =SUM(L19:L20) -> 4.625 | M21: =SUM(M19:M20) -> 5 | N21: =SUM(N19:N20) -> 5 | O21: =SUM(O19:O20) -> 5 | ... AA21: =SUM(AA19:AA20) -> 5
B23: PRICING
B24: Base Steel Price | D24: (EUR/Unit) | H24: =Inputs!H$91 -> 865.94573 | I24: =Inputs!I$91 -> 883.26464 | J24: =Inputs!J$91 -> 900.92994 | K24: =Inputs!K$91 -> 918.0476 | L24: =Inputs!L$91 -> 935.49051 | M24: =Inputs!M$91 -> 953.26483 | N24: =Inputs!N$91 -> 971.37686 | O24: =Inputs!O$91 -> 988.86164 | ... AA24: =Inputs!AA$91 -> 1202.2517
B25: Green Offtake Price | D25: =Inputs!$H$94 -> 0.25 | H25: =H$24*(1+Inputs!H$94) -> 1082.4322 | I25: =I$24*(1+Inputs!I$94) -> 1104.0808 | J25: =J$24*(1+Inputs!J$94) -> 1126.1624 | K25: =K$24*(1+Inputs!K$94) -> 1147.5595 | L25: =L$24*(1+Inputs!L$94) -> 1169.3631 | M25: =M$24*(1+Inputs!M$94) -> 1191.581 | N25: =N$24*(1+Inputs!N$94) -> 1214.2211 | O25: =O$24*(1+Inputs!O$94) -> 1236.0771 | ... AA25: =AA$24*(1+Inputs!AA$94) -> 1502.8147
B26: Green Spot Price | D26: =Inputs!$H$101 -> 0.1 | H26: =H$24*(1+Inputs!H$101) -> 952.5403 | I26: =I$24*(1+Inputs!I$101) -> 971.59111 | J26: =J$24*(1+Inputs!J$101) -> 991.02293 | K26: =K$24*(1+Inputs!K$101) -> 1009.8524 | L26: =L$24*(1+Inputs!L$101) -> 1029.0396 | M26: =M$24*(1+Inputs!M$101) -> 1048.5913 | N26: =N$24*(1+Inputs!N$101) -> 1068.5145 | O26: =O$24*(1+Inputs!O$101) -> 1087.7478 | ... AA26: =AA$24*(1+Inputs!AA$101) -> 1322.4769
B28: REVENUE
B29: Offtake Coverage Share | D29: % | H29: =Inputs!H$108 -> 0.75 | I29: =Inputs!I$108 -> 0.75 | J29: =Inputs!J$108 -> 0.75 | K29: =Inputs!K$108 -> 0.75 | L29: =Inputs!L$108 -> 0.75 | M29: =Inputs!M$108 -> 0.75 | N29: =Inputs!N$108 -> 0.75 | O29: =Inputs!O$108 -> 0.75 | ... AA29: =Inputs!AA$108 -> 0.75
B30: Spot Share | D30: % | H30: =1-H$29 -> 0.25 | I30: =1-I$29 -> 0.25 | J30: =1-J$29 -> 0.25 | K30: =1-K$29 -> 0.25 | L30: =1-L$29 -> 0.25 | M30: =1-M$29 -> 0.25 | N30: =1-N$29 -> 0.25 | O30: =1-O$29 -> 0.25 | ... AA30: =1-AA$29 -> 0.25
B32: Offtake Revenue | D32: (EUR, mio) | H32: =H21*H29*H25 -> 1420.6922 | I32: =I21*I29*I25 -> 1759.6288 | J32: =J21*J29*J25 -> 2111.5545 | K32: =K21*K29*K25 -> 3657.8459 | L32: =L21*L29*L25 -> 4056.2284 | M32: =M21*M29*M25 -> 4468.4289 | N32: =N21*N29*N25 -> 4553.329 | O32: =O21*O29*O25 -> 4635.289 | ... AA32: =AA21*AA29*AA25 -> 5635.555
B33: Spot Revenue | D33: (EUR, mio) | H33: =H21*H30*H26 -> 416.73638 | I33: =I21*I30*I26 -> 516.15778 | J33: =J21*J30*J26 -> 619.38933 | K33: =K21*K30*K26 -> 1072.9681 | L33: =L21*L30*L26 -> 1189.827 | M33: =M21*M30*M26 -> 1310.7391 | N33: =N21*N30*N26 -> 1335.6432 | O33: =O21*O30*O26 -> 1359.6848 | ... AA33: =AA21*AA30*AA26 -> 1653.0961
B34: Total Revenue | D34: (EUR, mio) | H34: =SUM(H32:H33) -> 1837.4286 | I34: =SUM(I32:I33) -> 2275.7866 | J34: =SUM(J32:J33) -> 2730.9439 | K34: =SUM(K32:K33) -> 4730.8141 | L34: =SUM(L32:L33) -> 5246.0554 | M34: =SUM(M32:M33) -> 5779.168 | N34: =SUM(N32:N33) -> 5888.9722 | O34: =SUM(O32:O33) -> 5994.9737 | ... AA34: =SUM(AA32:AA33) -> 7288.6511
B35: Total Revenue | D35: (EUR, mio) | H35: 1300.749 | I35: 1640.9449 | J35: 2081.9489 | K35: 3503.9199 | L35: 3889.3511 | M35: 4397.1275 | N35: 4474.0773 | O35: 4552.3736 | P35: 4620.6592 | Q35: 4689.9691 | R35: 4760.3187 | S35: 4831.7234 | T35: 4904.1993 | U35: 4977.7623 | V35: 5052.4287 | W35: 5128.2151 | X35: 5205.1384 | Y35: 5283.2154 | Z35: 5362.4637 | AA35: 5442.9006
B38: Cost Schedule
B40: All figures in EUR millions unless stated
B41: {=CONCATENATE("Model Drivers: ",INDEX(Inputs!$B$96:$B$98,Inputs!$D$86)," & ",INDEX(Inputs!$B$143:$B$144,Inputs!$D$139)," Financing")} -> Model Drivers: Base Case & Two Phased Financing | F41: 2025 | G41: 2026 | H41: =Inputs!$F$8 -> 2027 | I41: =H41+1 -> 2028 | J41: =I41+1 -> 2029 | K41: =J41+1 -> 2030 | L41: =K41+1 -> 2031 | M41: =L41+1 -> 2032 | N41: =M41+1 -> 2033 | O41: =N41+1 -> 2034 | P41: =O41+1 -> 2035 | ... AA41: =Z41+1 -> 2046
B43: Total Steel Output | D43: (Mtpa/Year) | H43: =H21 -> 1.75 | I43: =I21 -> 2.125 | J43: =J21 -> 2.5 | K43: =K21 -> 4.25 | L43: =L21 -> 4.625 | M43: =M21 -> 5 | N43: =N21 -> 5 | O43: =O21 -> 5 | ... AA43: =AA21 -> 5
B44: Pellets (Iron Ore) Usage | D44: (Mtpa/Year) | H44: =H43*Inputs!$L$10 -> 2.625 | I44: =I43*Inputs!$L$10 -> 3.1875 | J44: =J43*Inputs!$L$10 -> 3.75 | K44: =K43*Inputs!$L$10 -> 6.375 | L44: =L43*Inputs!$L$10 -> 6.9375 | M44: =M43*Inputs!$L$10 -> 7.5 | N44: =N43*Inputs!$L$10 -> 7.5 | O44: =O43*Inputs!$L$10 -> 7.5 | ... AA44: =AA43*Inputs!$L$10 -> 7.5
B45: Electricity Usage | D45: TWh | H45: =H43/2.5*Inputs!$L$8 -> 4.9 | I45: =I43/2.5*Inputs!$L$8 -> 5.95 | J45: =J43/2.5*Inputs!$L$8 -> 7 | K45: =K43/2.5*Inputs!$L$8 -> 11.9 | L45: =L43/2.5*Inputs!$L$8 -> 12.95 | M45: =M43/2.5*Inputs!$L$8 -> 14 | N45: =N43/2.5*Inputs!$L$8 -> 14 | O45: =O43/2.5*Inputs!$L$8 -> 14 | ... AA45: =AA43/2.5*Inputs!$L$8 -> 14
B46: Scrap Usage | D46: (Mtpa/Year) | H46: =H43*Inputs!$L$11 -> 0.5425 | I46: =I43*Inputs!$L$11 -> 0.65875 | J46: =J43*Inputs!$L$11 -> 0.775 | K46: =K43*Inputs!$L$11 -> 1.3175 | L46: =L43*Inputs!$L$11 -> 1.43375 | M46: =M43*Inputs!$L$11 -> 1.55 | N46: =N43*Inputs!$L$11 -> 1.55 | O46: =O43*Inputs!$L$11 -> 1.55 | ... AA46: =AA43*Inputs!$L$11 -> 1.55
B47: Inflation | D47: % | H47: =Inputs!$F$88 -> 0.02 | I47: =Inputs!$F$88 -> 0.02 | J47: =Inputs!$F$88 -> 0.02 | K47: =Inputs!$F$88 -> 0.02 | L47: =Inputs!$F$88 -> 0.02 | M47: =Inputs!$F$88 -> 0.02 | N47: =Inputs!$F$88 -> 0.02 | O47: =Inputs!$F$88 -> 0.02 | ... AA47: =Inputs!$F$88 -> 0.02
B50: COGS
B51: Pellets (Iron Ore) Price | D51: (EUR/t) | H51: =Inputs!H$122 -> 108.24322 | I51: =Inputs!I$122 -> 110.40808 | J51: =Inputs!J$122 -> 112.61624 | K51: =Inputs!K$122 -> 114.75595 | L51: =Inputs!L$122 -> 116.93631 | M51: =Inputs!M$122 -> 119.1581 | N51: =Inputs!N$122 -> 121.42211 | O51: =Inputs!O$122 -> 123.60771 | ... AA51: =Inputs!AA$122 -> 150.28147
B52: Electricity Price | D52: MWh | H52: =Inputs!H$115 -> 54.121608 | I52: =Inputs!I$115 -> 55.20404 | J52: =Inputs!J$115 -> 56.308121 | K52: =Inputs!K$115 -> 57.377975 | L52: =Inputs!L$115 -> 58.468157 | M52: =Inputs!M$115 -> 59.579052 | N52: =Inputs!N$115 -> 60.711054 | O52: =Inputs!O$115 -> 61.803853 | ... AA52: =Inputs!AA$115 -> 75.140733
B53: Scrap Metal Price | D53: (EUR/t) | H53: =Inputs!$L$12 -> 385 | I53: =H53*(1+I$47) -> 392.7 | J53: =I53*(1+J$47) -> 400.554 | K53: =J53*(1+K$47) -> 408.56508 | L53: =K53*(1+L$47) -> 416.73638 | M53: =L53*(1+M$47) -> 425.07111 | N53: =M53*(1+N$47) -> 433.57253 | O53: =N53*(1+O$47) -> 442.24398 | P53: =O53*(1+P$47) -> 451.08886 | ... AA53: =Z53*(1+AA$47) -> 560.8723
B54: Consumables & Alloys | D54: (EUR/t) | H54: =Inputs!$L$13 -> 130 | I54: =H54*(1+I$47) -> 132.6 | J54: =I54*(1+J$47) -> 135.252 | K54: =J54*(1+K$47) -> 137.95704 | L54: =K54*(1+L$47) -> 140.71618 | M54: =L54*(1+M$47) -> 143.5305 | N54: =M54*(1+N$47) -> 146.40111 | O54: =N54*(1+O$47) -> 149.32914 | P54: =O54*(1+P$47) -> 152.31572 | ... AA54: =Z54*(1+AA$47) -> 189.38545
...
